Workbook
Name T_GRID: Tables!$A$2:$A$16
Name T_POWER: Tables!$B$2:$B$16
Name T_HEAT_RATE: Tables!$C$2:$C$16
Name T_EXHAUST_FLOW: Tables!$D$2:$D$16
Name T_EXHAUST_TEMP: Tables!$E$2:$E$16
Name RH_POWER: Tables!$F$2:$F$16
Name RH_HEAT_RATE: Tables!$G$2:$G$16
Name RH_EXHAUST_FLOW: Tables!$H$2:$H$16
Name RH_EXHAUST_TEMP: Tables!$I$2:$I$16
Name INLET_POWER: Tables!$J$2:$J$16
Name INLET_HEAT_RATE: Tables!$K$2:$K$16
Name INLET_EXHAUST_FLOW: Tables!$L$2:$L$16
Name INLET_EXHAUST_TEMP: Tables!$M$2:$M$16
Name EXHAUST_POWER: Tables!$N$2:$N$16
Name EXHAUST_HEAT_RATE: Tables!$O$2:$O$16
Name EXHAUST_EXHAUST_FLOW: Tables!$P$2:$P$16
Name EXHAUST_EXHAUST_TEMP: Tables!$Q$2:$Q$16
Name ISO_POWER_MW: Tables!$A$21
Name ISO_HEAT_RATE: Tables!$B$21
Name ISO_EXHAUST_FLOW: Tables!$C$21
Name ISO_EXHAUST_TEMP_C: Tables!$D$21
Name GTPERF_COMMAND: About!$A$25
Name DATASHEET_PATH: About!$A$27

Sheet Site tool
B1: Site performance: SGT-400 13 MW (public datasheet)
B2: Blue cells are inputs. Results use correction curves from the calibrated gtperf model; see the Check sheet for their error against the full model.
B4: Case
B5: Case name | D5: ISO | E5: Temperate, sea level | F5: Hot desert | G5: Tropical coast | H5: Cold, elevated
B6: Site conditions
B7: Ambient temperature | C7: °C | D7: 15 | E7: 10 | F7: 45 | G7: 32 | H7: -10
B8: Site altitude | C8: m | D8: 0 | E8: 30 | F8: 300 | G8: 10 | H8: 1500
B9: Relative humidity | C9: % | D9: 60 | E9: 80 | F9: 20 | G9: 85 | H9: 60
B10: Inlet pressure loss | C10: mbar | D10: 0 | E10: 8 | F10: 10 | G10: 8 | H10: 8
B11: Exhaust pressure loss | C11: mbar | D11: 0 | E11: 15 | F11: 25 | G11: 20 | H11: 15
B12: Degradation, output | C12: % | D12: 0 | E12: 0 | F12: 0 | G12: 0 | H12: 2
B13: Degradation, heat rate | C13: % | D13: 0 | E13: 0 | F13: 0 | G13: 0 | H13: 1
B14: Derived
B15: Ambient pressure (ISA) | C15: mbar | D15: =1013.25*(1-2.25577E-5*D8)^5.25588 | E15: =1013.25*(1-2.25577E-5*E8)^5.25588 | F15: =1013.25*(1-2.25577E-5*F8)^5.25588 | G15: =1013.25*(1-2.25577E-5*G8)^5.25588 | H15: =1013.25*(1-2.25577E-5*H8)^5.25588
B16: Pressure ratio to ISO, delta | C16: - | D16: =D15/1013.25 | E16: =E15/1013.25 | F16: =F15/1013.25 | G16: =G15/1013.25 | H16: =H15/1013.25
B17: Correction factors (site = ISO x product)
B18: Temperature, output | C18: - | D18: =FORECAST(D7,OFFSET(T_POWER,MIN(IFERROR(MATCH(D7,T_GRID,1),1),ROWS(T_GRID)-1)-1,0,2,1),OFFSET(T_GRID,MIN(IFERROR(MATCH(D7,T_GRID,1),1),ROWS(T_GRID)-1)-1,0,2,1)) | E18: =FORECAST(E7,OFFSET(T_POWER,MIN(IFERROR(MATCH(E7,T_GRID,1),1),ROWS(T_GRID)-1)-1,0,2,1),OFFSET(T_GRID,MIN(IFERROR(MATCH(E7,T_GRID,1),1),ROWS(T_GRID)-1)-1,0,2,1)) | F18: =FORECAST(F7,OFFSET(T_POWER,MIN(IFERROR(MATCH(F7,T_GRID,1),1),ROWS(T_GRID)-1)-1,0,2,1),OFFSET(T_GRID,MIN(IFERROR(MATCH(F7,T_GRID,1),1),ROWS(T_GRID)-1)-1,0,2,1)) | G18: =FORECAST(G7,OFFSET(T_POWER,MIN(IFERROR(MATCH(G7,T_GRID,1),1),ROWS(T_GRID)-1)-1,0,2,1),OFFSET(T_GRID,MIN(IFERROR(MATCH(G7,T_GRID,1),1),ROWS(T_GRID)-1)-1,0,2,1)) | H18: =FORECAST(H7,OFFSET(T_POWER,MIN(IFERROR(MATCH(H7,T_GRID,1),1),ROWS(T_GRID)-1)-1,0,2,1),OFFSET(T_GRID,MIN(IFERROR(MATCH(H7,T_GRID,1),1),ROWS(T_GRID)-1)-1,0,2,1))
B19: Altitude, output | C19: - | D19: =D16 | E19: =E16 | F19: =F16 | G19: =G16 | H19: =H16
B20: Humidity, output | C20: - | D20: =1+FORECAST(D7,OFFSET(RH_POWER,MIN(IFERROR(MATCH(D7,T_GRID,1),1),ROWS(T_GRID)-1)-1,0,2,1),OFFSET(T_GRID,MIN(IFERROR(MATCH(D7,T_GRID,1),1),ROWS(T_GRID)-1)-1,0,2,1))*(D9/100-0.6) | E20: =1+FORECAST(E7,OFFSET(RH_POWER,MIN(IFERROR(MATCH(E7,T_GRID,1),1),ROWS(T_GRID)-1)-1,0,2,1),OFFSET(T_GRID,MIN(IFERROR(MATCH(E7,T_GRID,1),1),ROWS(T_GRID)-1)-1,0,2,1))*(E9/100-0.6) | F20: =1+FORECAST(F7,OFFSET(RH_POWER,MIN(IFERROR(MATCH(F7,T_GRID,1),1),ROWS(T_GRID)-1)-1,0,2,1),OFFSET(T_GRID,MIN(IFERROR(MATCH(F7,T_GRID,1),1),ROWS(T_GRID)-1)-1,0,2,1))*(F9/100-0.6) | G20: =1+FORECAST(G7,OFFSET(RH_POWER,MIN(IFERROR(MATCH(G7,T_GRID,1),1),ROWS(T_GRID)-1)-1,0,2,1),OFFSET(T_GRID,MIN(IFERROR(MATCH(G7,T_GRID,1),1),ROWS(T_GRID)-1)-1,0,2,1))*(G9/100-0.6) | H20: =1+FORECAST(H7,OFFSET(RH_POWER,MIN(IFERROR(MATCH(H7,T_GRID,1),1),ROWS(T_GRID)-1)-1,0,2,1),OFFSET(T_GRID,MIN(IFERROR(MATCH(H7,T_GRID,1),1),ROWS(T_GRID)-1)-1,0,2,1))*(H9/100-0.6)
B21: Inlet loss, output | C21: - | D21: =1+FORECAST(D7,OFFSET(INLET_POWER,MIN(IFERROR(MATCH(D7,T_GRID,1),1),ROWS(T_GRID)-1)-1,0,2,1),OFFSET(T_GRID,MIN(IFERROR(MATCH(D7,T_GRID,1),1),ROWS(T_GRID)-1)-1,0,2,1))*D10/D16 | E21: =1+FORECAST(E7,OFFSET(INLET_POWER,MIN(IFERROR(MATCH(E7,T_GRID,1),1),ROWS(T_GRID)-1)-1,0,2,1),OFFSET(T_GRID,MIN(IFERROR(MATCH(E7,T_GRID,1),1),ROWS(T_GRID)-1)-1,0,2,1))*E10/E16 | F21: =1+FORECAST(F7,OFFSET(INLET_POWER,MIN(IFERROR(MATCH(F7,T_GRID,1),1),ROWS(T_GRID)-1)-1,0,2,1),OFFSET(T_GRID,MIN(IFERROR(MATCH(F7,T_GRID,1),1),ROWS(T_GRID)-1)-1,0,2,1))*F10/F16 | G21: =1+FORECAST(G7,OFFSET(INLET_POWER,MIN(IFERROR(MATCH(G7,T_GRID,1),1),ROWS(T_GRID)-1)-1,0,2,1),OFFSET(T_GRID,MIN(IFERROR(MATCH(G7,T_GRID,1),1),ROWS(T_GRID)-1)-1,0,2,1))*G10/G16 | H21: =1+FORECAST(H7,OFFSET(INLET_POWER,MIN(IFERROR(MATCH(H7,T_GRID,1),1),ROWS(T_GRID)-1)-1,0,2,1),OFFSET(T_GRID,MIN(IFERROR(MATCH(H7,T_GRID,1),1),ROWS(T_GRID)-1)-1,0,2,1))*H10/H16
B22: Exhaust loss, output | C22: - | D22: =1+FORECAST(D7,OFFSET(EXHAUST_POWER,MIN(IFERROR(MATCH(D7,T_GRID,1),1),ROWS(T_GRID)-1)-1,0,2,1),OFFSET(T_GRID,MIN(IFERROR(MATCH(D7,T_GRID,1),1),ROWS(T_GRID)-1)-1,0,2,1))*D11/D16 | E22: =1+FORECAST(E7,OFFSET(EXHAUST_POWER,MIN(IFERROR(MATCH(E7,T_GRID,1),1),ROWS(T_GRID)-1)-1,0,2,1),OFFSET(T_GRID,MIN(IFERROR(MATCH(E7,T_GRID,1),1),ROWS(T_GRID)-1)-1,0,2,1))*E11/E16 | F22: =1+FORECAST(F7,OFFSET(EXHAUST_POWER,MIN(IFERROR(MATCH(F7,T_GRID,1),1),ROWS(T_GRID)-1)-1,0,2,1),OFFSET(T_GRID,MIN(IFERROR(MATCH(F7,T_GRID,1),1),ROWS(T_GRID)-1)-1,0,2,1))*F11/F16 | G22: =1+FORECAST(G7,OFFSET(EXHAUST_POWER,MIN(IFERROR(MATCH(G7,T_GRID,1),1),ROWS(T_GRID)-1)-1,0,2,1),OFFSET(T_GRID,MIN(IFERROR(MATCH(G7,T_GRID,1),1),ROWS(T_GRID)-1)-1,0,2,1))*G11/G16 | H22: =1+FORECAST(H7,OFFSET(EXHAUST_POWER,MIN(IFERROR(MATCH(H7,T_GRID,1),1),ROWS(T_GRID)-1)-1,0,2,1),OFFSET(T_GRID,MIN(IFERROR(MATCH(H7,T_GRID,1),1),ROWS(T_GRID)-1)-1,0,2,1))*H11/H16
B23: Temperature, heat rate | C23: - | D23: =FORECAST(D7,OFFSET(T_HEAT_RATE,MIN(IFERROR(MATCH(D7,T_GRID,1),1),ROWS(T_GRID)-1)-1,0,2,1),OFFSET(T_GRID,MIN(IFERROR(MATCH(D7,T_GRID,1),1),ROWS(T_GRID)-1)-1,0,2,1)) | E23: =FORECAST(E7,OFFSET(T_HEAT_RATE,MIN(IFERROR(MATCH(E7,T_GRID,1),1),ROWS(T_GRID)-1)-1,0,2,1),OFFSET(T_GRID,MIN(IFERROR(MATCH(E7,T_GRID,1),1),ROWS(T_GRID)-1)-1,0,2,1)) | F23: =FORECAST(F7,OFFSET(T_HEAT_RATE,MIN(IFERROR(MATCH(F7,T_GRID,1),1),ROWS(T_GRID)-1)-1,0,2,1),OFFSET(T_GRID,MIN(IFERROR(MATCH(F7,T_GRID,1),1),ROWS(T_GRID)-1)-1,0,2,1)) | G23: =FORECAST(G7,OFFSET(T_HEAT_RATE,MIN(IFERROR(MATCH(G7,T_GRID,1),1),ROWS(T_GRID)-1)-1,0,2,1),OFFSET(T_GRID,MIN(IFERROR(MATCH(G7,T_GRID,1),1),ROWS(T_GRID)-1)-1,0,2,1)) | H23: =FORECAST(H7,OFFSET(T_HEAT_RATE,MIN(IFERROR(MATCH(H7,T_GRID,1),1),ROWS(T_GRID)-1)-1,0,2,1),OFFSET(T_GRID,MIN(IFERROR(MATCH(H7,T_GRID,1),1),ROWS(T_GRID)-1)-1,0,2,1))
B24: Altitude, heat rate | C24: - | D24: =1 | E24: =1 | F24: =1 | G24: =1 | H24: =1
B25: Humidity, heat rate | C25: - | D25: =1+FORECAST(D7,OFFSET(RH_HEAT_RATE,MIN(IFERROR(MATCH(D7,T_GRID,1),1),ROWS(T_GRID)-1)-1,0,2,1),OFFSET(T_GRID,MIN(IFERROR(MATCH(D7,T_GRID,1),1),ROWS(T_GRID)-1)-1,0,2,1))*(D9/100-0.6) | E25: =1+FORECAST(E7,OFFSET(RH_HEAT_RATE,MIN(IFERROR(MATCH(E7,T_GRID,1),1),ROWS(T_GRID)-1)-1,0,2,1),OFFSET(T_GRID,MIN(IFERROR(MATCH(E7,T_GRID,1),1),ROWS(T_GRID)-1)-1,0,2,1))*(E9/100-0.6) | F25: =1+FORECAST(F7,OFFSET(RH_HEAT_RATE,MIN(IFERROR(MATCH(F7,T_GRID,1),1),ROWS(T_GRID)-1)-1,0,2,1),OFFSET(T_GRID,MIN(IFERROR(MATCH(F7,T_GRID,1),1),ROWS(T_GRID)-1)-1,0,2,1))*(F9/100-0.6) | G25: =1+FORECAST(G7,OFFSET(RH_HEAT_RATE,MIN(IFERROR(MATCH(G7,T_GRID,1),1),ROWS(T_GRID)-1)-1,0,2,1),OFFSET(T_GRID,MIN(IFERROR(MATCH(G7,T_GRID,1),1),ROWS(T_GRID)-1)-1,0,2,1))*(G9/100-0.6) | H25: =1+FORECAST(H7,OFFSET(RH_HEAT_RATE,MIN(IFERROR(MATCH(H7,T_GRID,1),1),ROWS(T_GRID)-1)-1,0,2,1),OFFSET(T_GRID,MIN(IFERROR(MATCH(H7,T_GRID,1),1),ROWS(T_GRID)-1)-1,0,2,1))*(H9/100-0.6)
B26: Inlet loss, heat rate | C26: - | D26: =1+FORECAST(D7,OFFSET(INLET_HEAT_RATE,MIN(IFERROR(MATCH(D7,T_GRID,1),1),ROWS(T_GRID)-1)-1,0,2,1),OFFSET(T_GRID,MIN(IFERROR(MATCH(D7,T_GRID,1),1),ROWS(T_GRID)-1)-1,0,2,1))*D10/D16 | E26: =1+FORECAST(E7,OFFSET(INLET_HEAT_RATE,MIN(IFERROR(MATCH(E7,T_GRID,1),1),ROWS(T_GRID)-1)-1,0,2,1),OFFSET(T_GRID,MIN(IFERROR(MATCH(E7,T_GRID,1),1),ROWS(T_GRID)-1)-1,0,2,1))*E10/E16 | F26: =1+FORECAST(F7,OFFSET(INLET_HEAT_RATE,MIN(IFERROR(MATCH(F7,T_GRID,1),1),ROWS(T_GRID)-1)-1,0,2,1),OFFSET(T_GRID,MIN(IFERROR(MATCH(F7,T_GRID,1),1),ROWS(T_GRID)-1)-1,0,2,1))*F10/F16 | G26: =1+FORECAST(G7,OFFSET(INLET_HEAT_RATE,MIN(IFERROR(MATCH(G7,T_GRID,1),1),ROWS(T_GRID)-1)-1,0,2,1),OFFSET(T_GRID,MIN(IFERROR(MATCH(G7,T_GRID,1),1),ROWS(T_GRID)-1)-1,0,2,1))*G10/G16 | H26: =1+FORECAST(H7,OFFSET(INLET_HEAT_RATE,MIN(IFERROR(MATCH(H7,T_GRID,1),1),ROWS(T_GRID)-1)-1,0,2,1),OFFSET(T_GRID,MIN(IFERROR(MATCH(H7,T_GRID,1),1),ROWS(T_GRID)-1)-1,0,2,1))*H10/H16
B27: Exhaust loss, heat rate | C27: - | D27: =1+FORECAST(D7,OFFSET(EXHAUST_HEAT_RATE,MIN(IFERROR(MATCH(D7,T_GRID,1),1),ROWS(T_GRID)-1)-1,0,2,1),OFFSET(T_GRID,MIN(IFERROR(MATCH(D7,T_GRID,1),1),ROWS(T_GRID)-1)-1,0,2,1))*D11/D16 | E27: =1+FORECAST(E7,OFFSET(EXHAUST_HEAT_RATE,MIN(IFERROR(MATCH(E7,T_GRID,1),1),ROWS(T_GRID)-1)-1,0,2,1),OFFSET(T_GRID,MIN(IFERROR(MATCH(E7,T_GRID,1),1),ROWS(T_GRID)-1)-1,0,2,1))*E11/E16 | F27: =1+FORECAST(F7,OFFSET(EXHAUST_HEAT_RATE,MIN(IFERROR(MATCH(F7,T_GRID,1),1),ROWS(T_GRID)-1)-1,0,2,1),OFFSET(T_GRID,MIN(IFERROR(MATCH(F7,T_GRID,1),1),ROWS(T_GRID)-1)-1,0,2,1))*F11/F16 | G27: =1+FORECAST(G7,OFFSET(EXHAUST_HEAT_RATE,MIN(IFERROR(MATCH(G7,T_GRID,1),1),ROWS(T_GRID)-1)-1,0,2,1),OFFSET(T_GRID,MIN(IFERROR(MATCH(G7,T_GRID,1),1),ROWS(T_GRID)-1)-1,0,2,1))*G11/G16 | H27: =1+FORECAST(H7,OFFSET(EXHAUST_HEAT_RATE,MIN(IFERROR(MATCH(H7,T_GRID,1),1),ROWS(T_GRID)-1)-1,0,2,1),OFFSET(T_GRID,MIN(IFERROR(MATCH(H7,T_GRID,1),1),ROWS(T_GRID)-1)-1,0,2,1))*H11/H16
B28: Temperature, exhaust flow | C28: - | D28: =FORECAST(D7,OFFSET(T_EXHAUST_FLOW,MIN(IFERROR(MATCH(D7,T_GRID,1),1),ROWS(T_GRID)-1)-1,0,2,1),OFFSET(T_GRID,MIN(IFERROR(MATCH(D7,T_GRID,1),1),ROWS(T_GRID)-1)-1,0,2,1)) | E28: =FORECAST(E7,OFFSET(T_EXHAUST_FLOW,MIN(IFERROR(MATCH(E7,T_GRID,1),1),ROWS(T_GRID)-1)-1,0,2,1),OFFSET(T_GRID,MIN(IFERROR(MATCH(E7,T_GRID,1),1),ROWS(T_GRID)-1)-1,0,2,1)) | F28: =FORECAST(F7,OFFSET(T_EXHAUST_FLOW,MIN(IFERROR(MATCH(F7,T_GRID,1),1),ROWS(T_GRID)-1)-1,0,2,1),OFFSET(T_GRID,MIN(IFERROR(MATCH(F7,T_GRID,1),1),ROWS(T_GRID)-1)-1,0,2,1)) | G28: =FORECAST(G7,OFFSET(T_EXHAUST_FLOW,MIN(IFERROR(MATCH(G7,T_GRID,1),1),ROWS(T_GRID)-1)-1,0,2,1),OFFSET(T_GRID,MIN(IFERROR(MATCH(G7,T_GRID,1),1),ROWS(T_GRID)-1)-1,0,2,1)) | H28: =FORECAST(H7,OFFSET(T_EXHAUST_FLOW,MIN(IFERROR(MATCH(H7,T_GRID,1),1),ROWS(T_GRID)-1)-1,0,2,1),OFFSET(T_GRID,MIN(IFERROR(MATCH(H7,T_GRID,1),1),ROWS(T_GRID)-1)-1,0,2,1))
B29: Altitude, exhaust flow | C29: - | D29: =D16 | E29: =E16 | F29: =F16 | G29: =G16 | H29: =H16
B30: Humidity, exhaust flow | C30: - | D30: =1+FORECAST(D7,OFFSET(RH_EXHAUST_FLOW,MIN(IFERROR(MATCH(D7,T_GRID,1),1),ROWS(T_GRID)-1)-1,0,2,1),OFFSET(T_GRID,MIN(IFERROR(MATCH(D7,T_GRID,1),1),ROWS(T_GRID)-1)-1,0,2,1))*(D9/100-0.6) | E30: =1+FORECAST(E7,OFFSET(RH_EXHAUST_FLOW,MIN(IFERROR(MATCH(E7,T_GRID,1),1),ROWS(T_GRID)-1)-1,0,2,1),OFFSET(T_GRID,MIN(IFERROR(MATCH(E7,T_GRID,1),1),ROWS(T_GRID)-1)-1,0,2,1))*(E9/100-0.6) | F30: =1+FORECAST(F7,OFFSET(RH_EXHAUST_FLOW,MIN(IFERROR(MATCH(F7,T_GRID,1),1),ROWS(T_GRID)-1)-1,0,2,1),OFFSET(T_GRID,MIN(IFERROR(MATCH(F7,T_GRID,1),1),ROWS(T_GRID)-1)-1,0,2,1))*(F9/100-0.6) | G30: =1+FORECAST(G7,OFFSET(RH_EXHAUST_FLOW,MIN(IFERROR(MATCH(G7,T_GRID,1),1),ROWS(T_GRID)-1)-1,0,2,1),OFFSET(T_GRID,MIN(IFERROR(MATCH(G7,T_GRID,1),1),ROWS(T_GRID)-1)-1,0,2,1))*(G9/100-0.6) | H30: =1+FORECAST(H7,OFFSET(RH_EXHAUST_FLOW,MIN(IFERROR(MATCH(H7,T_GRID,1),1),ROWS(T_GRID)-1)-1,0,2,1),OFFSET(T_GRID,MIN(IFERROR(MATCH(H7,T_GRID,1),1),ROWS(T_GRID)-1)-1,0,2,1))*(H9/100-0.6)
B31: Inlet loss, exhaust flow | C31: - | D31: =1+FORECAST(D7,OFFSET(INLET_EXHAUST_FLOW,MIN(IFERROR(MATCH(D7,T_GRID,1),1),ROWS(T_GRID)-1)-1,0,2,1),OFFSET(T_GRID,MIN(IFERROR(MATCH(D7,T_GRID,1),1),ROWS(T_GRID)-1)-1,0,2,1))*D10/D16 | E31: =1+FORECAST(E7,OFFSET(INLET_EXHAUST_FLOW,MIN(IFERROR(MATCH(E7,T_GRID,1),1),ROWS(T_GRID)-1)-1,0,2,1),OFFSET(T_GRID,MIN(IFERROR(MATCH(E7,T_GRID,1),1),ROWS(T_GRID)-1)-1,0,2,1))*E10/E16 | F31: =1+FORECAST(F7,OFFSET(INLET_EXHAUST_FLOW,MIN(IFERROR(MATCH(F7,T_GRID,1),1),ROWS(T_GRID)-1)-1,0,2,1),OFFSET(T_GRID,MIN(IFERROR(MATCH(F7,T_GRID,1),1),ROWS(T_GRID)-1)-1,0,2,1))*F10/F16 | G31: =1+FORECAST(G7,OFFSET(INLET_EXHAUST_FLOW,MIN(IFERROR(MATCH(G7,T_GRID,1),1),ROWS(T_GRID)-1)-1,0,2,1),OFFSET(T_GRID,MIN(IFERROR(MATCH(G7,T_GRID,1),1),ROWS(T_GRID)-1)-1,0,2,1))*G10/G16 | H31: =1+FORECAST(H7,OFFSET(INLET_EXHAUST_FLOW,MIN(IFERROR(MATCH(H7,T_GRID,1),1),ROWS(T_GRID)-1)-1,0,2,1),OFFSET(T_GRID,MIN(IFERROR(MATCH(H7,T_GRID,1),1),ROWS(T_GRID)-1)-1,0,2,1))*H10/H16
B32: Exhaust loss, exhaust flow | C32: - | D32: =1+FORECAST(D7,OFFSET(EXHAUST_EXHAUST_FLOW,MIN(IFERROR(MATCH(D7,T_GRID,1),1),ROWS(T_GRID)-1)-1,0,2,1),OFFSET(T_GRID,MIN(IFERROR(MATCH(D7,T_GRID,1),1),ROWS(T_GRID)-1)-1,0,2,1))*D11/D16 | E32: =1+FORECAST(E7,OFFSET(EXHAUST_EXHAUST_FLOW,MIN(IFERROR(MATCH(E7,T_GRID,1),1),ROWS(T_GRID)-1)-1,0,2,1),OFFSET(T_GRID,MIN(IFERROR(MATCH(E7,T_GRID,1),1),ROWS(T_GRID)-1)-1,0,2,1))*E11/E16 | F32: =1+FORECAST(F7,OFFSET(EXHAUST_EXHAUST_FLOW,MIN(IFERROR(MATCH(F7,T_GRID,1),1),ROWS(T_GRID)-1)-1,0,2,1),OFFSET(T_GRID,MIN(IFERROR(MATCH(F7,T_GRID,1),1),ROWS(T_GRID)-1)-1,0,2,1))*F11/F16 | G32: =1+FORECAST(G7,OFFSET(EXHAUST_EXHAUST_FLOW,MIN(IFERROR(MATCH(G7,T_GRID,1),1),ROWS(T_GRID)-1)-1,0,2,1),OFFSET(T_GRID,MIN(IFERROR(MATCH(G7,T_GRID,1),1),ROWS(T_GRID)-1)-1,0,2,1))*G11/G16 | H32: =1+FORECAST(H7,OFFSET(EXHAUST_EXHAUST_FLOW,MIN(IFERROR(MATCH(H7,T_GRID,1),1),ROWS(T_GRID)-1)-1,0,2,1),OFFSET(T_GRID,MIN(IFERROR(MATCH(H7,T_GRID,1),1),ROWS(T_GRID)-1)-1,0,2,1))*H11/H16
B33: Degradation factor, output | C33: - | D33: =1-D12/100 | E33: =1-E12/100 | F33: =1-F12/100 | G33: =1-G12/100 | H33: =1-H12/100
B34: Degradation factor, heat rate | C34: - | D34: =1+D13/100 | E34: =1+E13/100 | F34: =1+F13/100 | G34: =1+G13/100 | H34: =1+H13/100
B35: Site performance
B36: Electrical output | C36: MW | D36: =ISO_POWER_MW*D18*D19*D20*D21*D22*D33 | E36: =ISO_POWER_MW*E18*E19*E20*E21*E22*E33 | F36: =ISO_POWER_MW*F18*F19*F20*F21*F22*F33 | G36: =ISO_POWER_MW*G18*G19*G20*G21*G22*G33 | H36: =ISO_POWER_MW*H18*H19*H20*H21*H22*H33
B37: Heat rate (LHV) | C37: kJ/kWh | D37: =ISO_HEAT_RATE*D23*D24*D25*D26*D27*D34 | E37: =ISO_HEAT_RATE*E23*E24*E25*E26*E27*E34 | F37: =ISO_HEAT_RATE*F23*F24*F25*F26*F27*F34 | G37: =ISO_HEAT_RATE*G23*G24*G25*G26*G27*G34 | H37: =ISO_HEAT_RATE*H23*H24*H25*H26*H27*H34
B38: Thermal efficiency (LHV) | C38: % | D38: =360000/D37 | E38: =360000/E37 | F38: =360000/F37 | G38: =360000/G37 | H38: =360000/H37
B39: Fuel heat input (LHV) | C39: MW | D39: =D36*D37/3600 | E39: =E36*E37/3600 | F39: =F36*F37/3600 | G39: =G36*G37/3600 | H39: =H36*H37/3600
B40: Exhaust flow | C40: kg/s | D40: =ISO_EXHAUST_FLOW*D28*D29*D30*D31*D32 | E40: =ISO_EXHAUST_FLOW*E28*E29*E30*E31*E32 | F40: =ISO_EXHAUST_FLOW*F28*F29*F30*F31*F32 | G40: =ISO_EXHAUST_FLOW*G28*G29*G30*G31*G32 | H40: =ISO_EXHAUST_FLOW*H28*H29*H30*H31*H32
B41: Exhaust temperature | C41: °C | D41: =ISO_EXHAUST_TEMP_C+FORECAST(D7,OFFSET(T_EXHAUST_TEMP,MIN(IFERROR(MATCH(D7,T_GRID,1),1),ROWS(T_GRID)-1)-1,0,2,1),OFFSET(T_GRID,MIN(IFERROR(MATCH(D7,T_GRID,1),1),ROWS(T_GRID)-1)-1,0,2,1))+FORECAST(D7,OFFSET(RH_EXHAUST_TEMP,MIN(IFERROR(MATCH(D7,T_GRID,1),1),ROWS(T_GRID)-1)-1,0,2,1),OFFSET(T_GRID,MIN(IFERROR(MATCH(D7,T_GRID,1),1),ROWS(T_GRID)-1)-1,0,2,1))*(D9/100-0.6)+FORECAST(D7,OFFSET(INLET_EXHAUST_TEMP,MIN(IFERROR(MATCH(D7,T_GRID,1),1),ROWS(T_GRID)-1)-1,0,2,1),OFFSET(T_GRID,MIN(IFERROR(MATCH(D7,T_GRID,1),1),ROWS(T_GRID)-1)-1,0,2,1))*D10/D16+FORECAST(D7,OFFSET(EXHAUST_EXHAUST_TEMP,MIN(IFERROR(MATCH(D7,T_GRID,1),1),ROWS(T_GRID)-1)-1,0,2,1),OFFSET(T_GRID,MIN(IFERROR(MATCH(D7,T_GRID,1),1),ROWS(T_GRID)-1)-1,0,2,1))*D11/D16 | E41: =ISO_EXHAUST_TEMP_C+FORECAST(E7,OFFSET(T_EXHAUST_TEMP,MIN(IFERROR(MATCH(E7,T_GRID,1),1),ROWS(T_GRID)-1)-1,0,2,1),OFFSET(T_GRID,MIN(IFERROR(MATCH(E7,T_GRID,1),1),ROWS(T_GRID)-1)-1,0,2,1))+FORECAST(E7,OFFSET(RH_EXHAUST_TEMP,MIN(IFERROR(MATCH(E7,T_GRID,1),1),ROWS(T_GRID)-1)-1,0,2,1),OFFSET(T_GRID,MIN(IFERROR(MATCH(E7,T_GRID,1),1),ROWS(T_GRID)-1)-1,0,2,1))*(E9/100-0.6)+FORECAST(E7,OFFSET(INLET_EXHAUST_TEMP,MIN(IFERROR(MATCH(E7,T_GRID,1),1),ROWS(T_GRID)-1)-1,0,2,1),OFFSET(T_GRID,MIN(IFERROR(MATCH(E7,T_GRID,1),1),ROWS(T_GRID)-1)-1,0,2,1))*E10/E16+FORECAST(E7,OFFSET(EXHAUST_EXHAUST_TEMP,MIN(IFERROR(MATCH(E7,T_GRID,1),1),ROWS(T_GRID)-1)-1,0,2,1),OFFSET(T_GRID,MIN(IFERROR(MATCH(E7,T_GRID,1),1),ROWS(T_GRID)-1)-1,0,2,1))*E11/E16 | F41: =ISO_EXHAUST_TEMP_C+FORECAST(F7,OFFSET(T_EXHAUST_TEMP,MIN(IFERROR(MATCH(F7,T_GRID,1),1),ROWS(T_GRID)-1)-1,0,2,1),OFFSET(T_GRID,MIN(IFERROR(MATCH(F7,T_GRID,1),1),ROWS(T_GRID)-1)-1,0,2,1))+FORECAST(F7,OFFSET(RH_EXHAUST_TEMP,MIN(IFERROR(MATCH(F7,T_GRID,1),1),ROWS(T_GRID)-1)-1,0,2,1),OFFSET(T_GRID,MIN(IFERROR(MATCH(F7,T_GRID,1),1),ROWS(T_GRID)-1)-1,0,2,1))*(F9/100-0.6)+FORECAST(F7,OFFSET(INLET_EXHAUST_TEMP,MIN(IFERROR(MATCH(F7,T_GRID,1),1),ROWS(T_GRID)-1)-1,0,2,1),OFFSET(T_GRID,MIN(IFERROR(MATCH(F7,T_GRID,1),1),ROWS(T_GRID)-1)-1,0,2,1))*F10/F16+FORECAST(F7,OFFSET(EXHAUST_EXHAUST_TEMP,MIN(IFERROR(MATCH(F7,T_GRID,1),1),ROWS(T_GRID)-1)-1,0,2,1),OFFSET(T_GRID,MIN(IFERROR(MATCH(F7,T_GRID,1),1),ROWS(T_GRID)-1)-1,0,2,1))*F11/F16 | G41: =ISO_EXHAUST_TEMP_C+FORECAST(G7,OFFSET(T_EXHAUST_TEMP,MIN(IFERROR(MATCH(G7,T_GRID,1),1),ROWS(T_GRID)-1)-1,0,2,1),OFFSET(T_GRID,MIN(IFERROR(MATCH(G7,T_GRID,1),1),ROWS(T_GRID)-1)-1,0,2,1))+FORECAST(G7,OFFSET(RH_EXHAUST_TEMP,MIN(IFERROR(MATCH(G7,T_GRID,1),1),ROWS(T_GRID)-1)-1,0,2,1),OFFSET(T_GRID,MIN(IFERROR(MATCH(G7,T_GRID,1),1),ROWS(T_GRID)-1)-1,0,2,1))*(G9/100-0.6)+FORECAST(G7,OFFSET(INLET_EXHAUST_TEMP,MIN(IFERROR(MATCH(G7,T_GRID,1),1),ROWS(T_GRID)-1)-1,0,2,1),OFFSET(T_GRID,MIN(IFERROR(MATCH(G7,T_GRID,1),1),ROWS(T_GRID)-1)-1,0,2,1))*G10/G16+FORECAST(G7,OFFSET(EXHAUST_EXHAUST_TEMP,MIN(IFERROR(MATCH(G7,T_GRID,1),1),ROWS(T_GRID)-1)-1,0,2,1),OFFSET(T_GRID,MIN(IFERROR(MATCH(G7,T_GRID,1),1),ROWS(T_GRID)-1)-1,0,2,1))*G11/G16 | H41: =ISO_EXHAUST_TEMP_C+FORECAST(H7,OFFSET(T_EXHAUST_TEMP,MIN(IFERROR(MATCH(H7,T_GRID,1),1),ROWS(T_GRID)-1)-1,0,2,1),OFFSET(T_GRID,MIN(IFERROR(MATCH(H7,T_GRID,1),1),ROWS(T_GRID)-1)-1,0,2,1))+FORECAST(H7,OFFSET(RH_EXHAUST_TEMP,MIN(IFERROR(MATCH(H7,T_GRID,1),1),ROWS(T_GRID)-1)-1,0,2,1),OFFSET(T_GRID,MIN(IFERROR(MATCH(H7,T_GRID,1),1),ROWS(T_GRID)-1)-1,0,2,1))*(H9/100-0.6)+FORECAST(H7,OFFSET(INLET_EXHAUST_TEMP,MIN(IFERROR(MATCH(H7,T_GRID,1),1),ROWS(T_GRID)-1)-1,0,2,1),OFFSET(T_GRID,MIN(IFERROR(MATCH(H7,T_GRID,1),1),ROWS(T_GRID)-1)-1,0,2,1))*H10/H16+FORECAST(H7,OFFSET(EXHAUST_EXHAUST_TEMP,MIN(IFERROR(MATCH(H7,T_GRID,1),1),ROWS(T_GRID)-1)-1,0,2,1),OFFSET(T_GRID,MIN(IFERROR(MATCH(H7,T_GRID,1),1),ROWS(T_GRID)-1)-1,0,2,1))*H11/H16
...

Sheet Tables
A1: temperature_C | B1: t_power | C1: t_heat_rate | D1: t_exhaust_flow | E1: t_exhaust_temp | F1: rh_power | G1: rh_heat_rate | H1: rh_exhaust_flow | I1: rh_exhaust_temp | J1: inlet_power | K1: inlet_heat_rate | L1: inlet_exhaust_flow | M1: inlet_exhaust_temp | N1: exhaust_power | O1: exhaust_heat_rate | P1: exhaust_exhaust_flow | Q1: exhaust_exhaust_temp | R1: control
A2: -20 | B2: 1.335156 | C2: 0.92526905 | D2: 1.243493 | E2: -53.816083 | F2: -0.00056910425 | G2: 0.00028378202 | H2: -0.0005717875 | I2: -0.095983267 | J2: -0.0013911684 | K2: 0.00047175924 | L2: -0.00098642489 | M2: 0.17603279 | N2: -0.00040205307 | O2: 0.00046811411 | P2: 5.0166509e-07 | Q2: 0.17386313 | R2: gas generator speed
A3: -15 | B3: 1.3007025 | C3: 0.93272819 | D3: 1.2126755 | E3: -43.819148 | F3: -0.00086423987 | G3: 0.00043802362 | H3: -0.00087217574 | I3: -0.14377836 | J3: -0.0013954175 | K3: 0.00047890348 | L3: -0.00098642579 | M3: 0.17923632 | N3: -0.00040626329 | O3: 0.00047523811 | P3: 5.007219e-07 | Q3: 0.17703745 | R3: gas generator speed
A4: -10 | B4: 1.2677257 | C4: 0.940286 | D4: 1.1830669 | E4: -33.787406 | F4: -0.0012896193 | G4: 0.0006640617 | H4: -0.0013069063 | I4: -0.2115679 | J4: -0.0013995967 | K4: 0.00048603978 | L4: -0.00098643048 | M4: 0.18247353 | N4: -0.00041040341 | O4: 0.00048235464 | P4: 4.959709e-07 | Q4: 0.18024542 | R4: gas generator speed
A5: -5 | B5: 1.2314879 | C5: 0.94847308 | D5: 1.1527471 | E5: -24.341273 | F5: 0.0024726795 | G5: 0.00035525554 | H5: -8.5781803e-05 | I5: 0.41076965 | J5: -0.0015369204 | K5: 0.00051437912 | L5: -0.0010423726 | M5: 0.16401646 | N5: -0.00054835254 | O5: 0.00051145424 | P5: -5.592641e-05 | Q5: 0.16190267 | R5: temperature
A6: 0 | B6: 1.1695461 | C6: 0.96020765 | D6: 1.1126677 | E6: -18.512101 | F6: 0.003659115 | G6: 0.00046516544 | H6: -9.8535248e-05 | I6: 0.5762484 | J6: -0.0015605173 | K6: 0.00053364335 | L6: -0.0010482149 | M6: 0.1675187 | N6: -0.00057193481 | O6: 0.00053080958 | P6: -6.1828498e-05 | Q6: 0.16538191 | R6: temperature
A7: 5 | B7: 1.1103574 | C7: 0.97266388 | D7: 1.0738918 | E7: -12.523112 | F7: 0.0053365861 | G7: 0.00058892276 | H7: -0.00010285278 | I7: 0.79467431 | J7: -0.0015858036 | K7: 0.0005541172 | L7: -0.0010546847 | M7: 0.17118964 | N7: -0.00059721103 | O7: 0.00055139868 | P7: -6.8366632e-05 | Q7: 0.16903105 | R7: temperature
A8: 10 | B8: 1.0538568 | C8: 0.98590574 | D8: 1.0363551 | E8: -6.3581003 | F8: 0.007676612 | G8: 0.00071702525 | H8: -9.0285948e-05 | I8: 1.0780383 | J8: -0.0016129215 | K8: 0.00057589232 | L8: -0.0010618467 | M8: 0.1750377 | N8: -0.00062432475 | O8: 0.00057331756 | P8: -7.5606875e-05 | Q8: 0.17285895 | R8: temperature
A9: 15 | B9: 1 | C9: 1 | D9: 1 | E9: -1.7053026e-12 | F9: 0.010899195 | G9: 0.00083186652 | H9: -4.8376217e-05 | I9: 1.4395387 | J9: -0.001642012 | K9: 0.00059905654 | L9: -0.001069768 | M9: 0.17906852 | N9: -0.00065341871 | O9: 0.00059665911 | P9: -8.3617822e-05 | Q9: 0.17687174 | R9: temperature
A10: 20 | B10: 0.94876367 | C10: 1.0150145 | D10: 0.96477618 | E10: 6.5687476 | F10: 0.015282656 | G10: 0.000904514 | H10: 4.0323855e-05 | I10: 1.8933324 | J10: -0.0016732081 | K10: 0.00062368771 | L10: -0.0010785157 | M10: 0.18328327 | N10: -0.00068462767 | O10: 0.00062150688 | P10: -9.2468373e-05 | Q10: 0.18107118 | R10: temperature
A11: 25 | B11: 0.90014602 | C11: 1.0310158 | D11: 0.93064072 | E11: 13.36567 | F11: 0.021174086 | G11: 0.00089096835 | H11: 0.00019910989 | I11: 2.4542637 | J11: -0.0017066247 | K11: 0.00064984519 | L11: -0.0010881543 | M11: 0.18767644 | N11: -0.00071806913 | O11: 0.00064792666 | P11: -0.00010222495 | Q11: 0.18545242 | R11: temperature
A12: 30 | B12: 0.85416664 | C12: 1.0480655 | D12: 0.89755822 | E12: 20.4076 | F12: 0.02900001 | G12: 0.0007280813 | H12: 0.00045773593 | I12: 3.1376664 | J12: -0.00174235 | K12: 0.00067755973 | L12: -0.0010987437 | M12: 0.19223301 | N12: -0.00075383441 | O12: 0.00067595627 | P12: -0.00011294954 | Q12: 0.19000122 | R12: temperature
A13: 35 | B13: 0.81086514 | C13: 1.0662169 | D13: 0.86550011 | E13: 27.709957 | F13: 0.039277468 | G13: 0.00032915587 | H13: 0.00085307579 | I13: 3.9593512 | J13: -0.0017804446 | K13: 0.00070682508 | L13: -0.0011103423 | M13: 0.19692576 | N13: -0.00079198955 | O13: 0.00070559764 | P13: -0.00012470399 | Q13: 0.19469125 | R13: temperature
... A16: 50 | B16: 0.69756029 | C16: 1.1276758 | D16: 0.77518123 | E16: 51.312725 | F16: 0.092028575 | G16: -0.003788917 | H16: 0.0036175047 | I16: 7.3903763 | J16: -0.0019115137 | K16: 0.00080414233 | L16: -0.0011531883 | M16: 0.2115132 | N16: -0.00092372497 | O16: 0.00080464722 | P16: -0.00016835508 | Q16: 0.20933747 | R16: temperature
A18: Ratios to ISO for t_*; exhaust temperature columns are kelvin. rh_* per unit RH about 60%, inlet_* per mbar of inlet loss, exhaust_* per mbar of exhaust loss, all at sea level.
A20: power_MW | B20: heat_rate | C20: exhaust_flow | D20: exhaust_temp_C
A21: 12.9 | B21: 10294 | C21: 40 | D21: 550.19915

Sheet Check
B1: Workbook formulas against the full gtperf model
B2: Full-model values were computed when the workbook was generated, for the cases as generated. If you change a case on the Site tool sheet the error column no longer applies.
B4: Case | C4: Quantity | D4: Full model | E4: Workbook | F4: Error
B5: ISO | C5: Output, MW | D5: 12.9 | E5: ='Site tool'!D36 | F5: =E5/D5-1
B6: ISO | C6: Heat rate, kJ/kWh | D6: 10294 | E6: ='Site tool'!D37 | F6: =E6/D6-1
B7: ISO | C7: Exhaust flow, kg/s | D7: 40 | E7: ='Site tool'!D40 | F7: =E7/D7-1
B8: ISO | C8: Exhaust temperature, °C | D8: 550.19915 | E8: ='Site tool'!D41 | F8: =E8-D8
B9: Temperate, sea level | C9: Output, MW | D9: 13.264726 | E9: ='Site tool'!E36 | F9: =E9/D9-1
B10: Temperate, sea level | C10: Heat rate, kJ/kWh | D10: 10285.55 | E10: ='Site tool'!E37 | F10: =E10/D10-1
B11: Temperate, sea level | C11: Exhaust flow, kg/s | D11: 40.906997 | E11: ='Site tool'!E40 | F11: =E11/D11-1
B12: Temperate, sea level | C12: Exhaust temperature, °C | D12: 548.07831 | E12: ='Site tool'!E41 | F12: =E12-D12
B13: Hot desert | C13: Output, MW | D13: 8.4889958 | E13: ='Site tool'!F36 | F13: =E13/D13-1
B14: Hot desert | C14: Heat rate, kJ/kWh | D14: 11725.863 | E14: ='Site tool'!F37 | F14: =E14/D14-1
B15: Hot desert | C15: Exhaust flow, kg/s | D15: 30.521417 | E15: ='Site tool'!F40 | F15: =E15/D15-1
B16: Hot desert | C16: Exhaust temperature, °C | D16: 598.6244 | E16: ='Site tool'!F41 | F16: =E16-D16
B17: Tropical coast | C17: Output, MW | D17: 10.548692 | E17: ='Site tool'!G36 | F17: =E17/D17-1
B18: Tropical coast | C18: Heat rate, kJ/kWh | D18: 11074.217 | E18: ='Site tool'!G37 | F18: =E18/D18-1
B19: Tropical coast | C19: Exhaust flow, kg/s | D19: 34.952008 | E19: ='Site tool'!G40 | F19: =E19/D19-1
B20: Tropical coast | C20: Exhaust temperature, °C | D20: 579.75506 | E20: ='Site tool'!G41 | F20: =E20-D20
B21: Cold, elevated | C21: Output, MW | D21: 13.094553 | E21: ='Site tool'!H36 | F21: =E21/D21-1
B22: Cold, elevated | C22: Heat rate, kJ/kWh | D22: 9908.1583 | E22: ='Site tool'!H37 | F22: =E22/D22-1
B23: Cold, elevated | C23: Exhaust flow, kg/s | D23: 39.11173 | E23: ='Site tool'!H40 | F23: =E23/D23-1
B24: Cold, elevated | C24: Exhaust temperature, °C | D24: 521.39943 | E24: ='Site tool'!H41 | F24: =E24-D24

Sheet About
A1: gtperf site performance tool
A2: Engine: SGT-400 13 MW (public datasheet).
A4: Method
A5: The Tables sheet holds corrections computed from the calibrated gtperf off-design model at sea level, every 5 °C from -20 to 50 °C:
A6: t_*: output, heat rate and exhaust flow as ratios to ISO, exhaust temperature as a change in K.
A7: rh_*, inlet_*, exhaust_*: linear sensitivities to humidity and to inlet and exhaust pressure loss.
A8: Altitude is applied as the ISA pressure ratio delta (output and flow scale with delta, heat rate and exhaust temperature do not), which is exact for dry air by similarity.
A9: Losses are divided by delta because their effect depends on the loss as a fraction of ambient pressure.
A10: Effects are applied in a fixed order and multiplied, matching gtperf.site.site_performance.
A12: Limits
A13: Base load, natural gas as calibrated, new and clean unless degradation is entered. Fuel changes, part load and transient behaviour need the full model.
A15: Regenerating
... A27: /home/claude/gtperf/examples/sgt400_13mw.toml
